Workbook

Sheet 見積書
C1: 見積書
Q4: 見積No.: | T4: 000001
A5: 株式会社 | J5: 御中 | Q5: 発行日: | S5: =TODAY() -> 46154
A6: 下記の通り、御請求申し上げます。
A8: ◆ 件名 | Q8: ◆ 会社名
A9: 業務委託報酬
A10: ◆ 有効期限 | Q10: ◆ 住所
A11: 46080 | Q11: 神奈川県横浜市神奈川区
A12: ◆ 支払い条件 | Q12: 西神奈川3-17-22
A13: 現場稼働にて | Q13: ◆ 振込先
Q14: GMOあおぞらネット銀行
B15: 合計金額 | E15: =O73 -> 1744721 | L15: 円（税込） | Q15: 法人営業部 普通 2010373
Q16: ド）スマートセールス
A18: No | B18: 摘要 | O18: 数量 | R18: 単価 | U18: 金額
B19: ヤマダ大船 2026/02/01 原田・安達 | O19: 2 | Q19: 日 | R19: 30000 | U19: =O19*R19 -> 60000
A20: 2 | B20: コジマビックカメラ江北駅前店 2026/02/01-02/03 鈴木 | O20: 3 | Q20: 日 | R20: 30000 | U20: =O20*R20 -> 90000
A21: 3 | B21: ケーズデンキ新浦安 2/6,7,8,9 鈴木 | O21: 4 | Q21: 日 | R21: 30000 | U21: =O21*R21 -> 120000
A22: 4 | B22: コジマ宇都宮 2/6,7,8 塩田 | O22: 3 | Q22: 日 | R22: 30000 | U22: =O22*R22 -> 90000
A23: 5 | B23: コジマ用賀 2/7,8 安達 | O23: 2 | Q23: 日 | R23: 28000 | U23: =O23*R23 -> 56000
A24: 6 | B24: ビックカメラ成城 2026/02/10、11 鈴木 | O24: 2 | Q24: 日 | R24: 30000 | U24: =O24*R24 -> 60000
A25: 7 | B25: コジマ用賀 2/7,8,9,10,11 原田 | O25: 5 | Q25: 日 | R25: 30000 | U25: =O25*R25 -> 150000
A26: 8 | B26: ビック八王子2026/02/14,15 安達 | O26: 2 | Q26: 日 | R26: 33000 | U26: =O26*R26 -> 66000
A27: 9 | B27: ヤマダデンキTL柏店 2026/02/13,14,15,16 鈴木原田 | O27: 8 | Q27: 日 | R27: 30000 | U27: =O27*R27 -> 240000
A28: 10 | B28: コジマさくら 2/15 塩田 | O28: 1 | Q28: 日 | R28: 30000 | U28: =O28*R28 -> 30000
A29: 11 | B29: ケーズ東松山 2026/02/20,21,22,23 原田 | O29: 4 | Q29: 日 | R29: 30000 | U29: =O29*R29 -> 120000
A30: 12 | B30: ケーズ鹿沼 2026/02/26,27,28 原田 | O30: 3 | Q30: 日 | R30: 30000 | U30: =O30*R30 -> 90000
A31: 13 | B31: コジマ宇都宮 2026/02/20,21,22,23 塩田 | O31: 4 | Q31: 日 | R31: 30000 | U31: =O31*R31 -> 120000
... A34: 16 | B34: ケーズデンキ足立店 2026/02/28 鈴木 | O34: 1 | Q34: 日 | R34: 30000 | U34: =O34*R34 -> 30000
B35: 交通費 | U35: =O35*R35 -> 0
B36: 鈴木 | O36: 1 | Q36: 式 | R36: 38366 | U36: =O36*R36 -> 38366
B37: 安達 | O37: 1 | Q37: 式 | R37: 11976 | U37: =O37*R37 -> 11976
B38: 原田 | O38: 1 | Q38: 式 | R38: 63768 | U38: =O38*R38 -> 63768
U39: =O39*R39 -> 0
U40: =O40*R40 -> 0
U41: =O41*R41 -> 0
U42: =O42*R42 -> 0
U43: =O43*R43 -> 0
U44: =O44*R44 -> 0
A45: 17 | U45: =O45*R45 -> 0
A46: 18 | U46: =O46*R46 -> 0
...

Sheet 請求書
C1: 御請求書
Q4: 請求書No.: | T4: ='見積書'!T4 -> 000001
A5: ='見積書'!A5 -> 株式会社 | J5: 御中 | Q5: 発行日: | S5: ='見積書'!S5 -> 46154
A6: 下記の通りご請求申し上げます。
A8: ◆ 件名 | Q8: ◆ 会社名
A9: 業務委託報酬
A10: ◆ お支払い期限 | Q10: ◆ 住所
A11: ='見積書'!A11 -> 46080 | Q11: 神奈川県横浜市神奈川区
Q12: 西神奈川3-17-22
Q13: ◆ 振込先
Q14: GMOあおぞらネット銀行
B15: 合計金額 | E15: ='見積書'!E15 -> 1744721 | L15: 円（税込） | Q15: 法人営業部 普通 2010373
Q16: ド）スマートセールス
A18: No | B18: 摘要 | O18: 数量 | R18: 単価 | U18: 金額
B19: ='見積書'!B19 -> ヤマダ大船 2026/02/01 原田・安達 | O19: ='見積書'!O19 -> 2 | Q19: ='見積書'!Q19 -> 日 | R19: ='見積書'!R19 -> 30000 | U19: ='見積書'!U19 -> 60000
A20: 2 | B20: ='見積書'!B20 -> コジマビックカメラ江北駅前店 2026/02/01-02/03 鈴木 | O20: ='見積書'!O20 -> 3 | Q20: ='見積書'!Q20 -> 日 | R20: ='見積書'!R20 -> 30000 | U20: ='見積書'!U20 -> 90000
A21: 3 | B21: ='見積書'!B21 -> ケーズデンキ新浦安 2/6,7,8,9 鈴木 | O21: ='見積書'!O21 -> 4 | Q21: ='見積書'!Q21 -> 日 | R21: ='見積書'!R21 -> 30000 | U21: ='見積書'!U21 -> 120000
A22: 4 | B22: ='見積書'!B22 -> コジマ宇都宮 2/6,7,8 塩田 | O22: ='見積書'!O22 -> 3 | Q22: ='見積書'!Q22 -> 日 | R22: ='見積書'!R22 -> 30000 | U22: ='見積書'!U22 -> 90000
A23: 5 | B23: ='見積書'!B23 -> コジマ用賀 2/7,8 安達 | O23: ='見積書'!O23 -> 2 | Q23: ='見積書'!Q23 -> 日 | R23: ='見積書'!R23 -> 28000 | U23: ='見積書'!U23 -> 56000
A24: 6 | B24: ='見積書'!B24 -> ビックカメラ成城 2026/02/10、11 鈴木 | O24: ='見積書'!O24 -> 2 | Q24: ='見積書'!Q24 -> 日 | R24: ='見積書'!R24 -> 30000 | U24: ='見積書'!U24 -> 60000
A25: 7 | B25: ='見積書'!B25 -> コジマ用賀 2/7,8,9,10,11 原田 | O25: ='見積書'!O25 -> 5 | Q25: ='見積書'!Q25 -> 日 | R25: ='見積書'!R25 -> 30000 | U25: ='見積書'!U25 -> 150000
A26: 8 | B26: ='見積書'!B26 -> ビック八王子2026/02/14,15 安達 | O26: ='見積書'!O26 -> 2 | Q26: ='見積書'!Q26 -> 日 | R26: ='見積書'!R26 -> 33000 | U26: ='見積書'!U26 -> 66000
A27: 9 | B27: ='見積書'!B27 -> ヤマダデンキTL柏店 2026/02/13,14,15,16 鈴木原田 | O27: ='見積書'!O27 -> 8 | Q27: ='見積書'!Q27 -> 日 | R27: ='見積書'!R27 -> 30000 | U27: ='見積書'!U27 -> 240000
A28: 10 | B28: ='見積書'!B28 -> コジマさくら 2/15 塩田 | O28: ='見積書'!O28 -> 1 | Q28: ='見積書'!Q28 -> 日 | R28: ='見積書'!R28 -> 30000 | U28: ='見積書'!U28 -> 30000
A29: 11 | B29: ='見積書'!B29 -> ケーズ東松山 2026/02/20,21,22,23 原田 | O29: ='見積書'!O29 -> 4 | Q29: ='見積書'!Q29 -> 日 | R29: ='見積書'!R29 -> 30000 | U29: ='見積書'!U29 -> 120000
A30: 12 | B30: ='見積書'!B30 -> ケーズ鹿沼 2026/02/26,27,28 原田 | O30: ='見積書'!O30 -> 3 | Q30: ='見積書'!Q30 -> 日 | R30: ='見積書'!R30 -> 30000 | U30: ='見積書'!U30 -> 90000
A31: 13 | B31: ='見積書'!B31 -> コジマ宇都宮 2026/02/20,21,22,23 塩田 | O31: ='見積書'!O31 -> 4 | Q31: ='見積書'!Q31 -> 日 | R31: ='見積書'!R31 -> 30000 | U31: ='見積書'!U31 -> 120000
... A34: 16 | B34: ='見積書'!B34 -> ケーズデンキ足立店 2026/02/28 鈴木 | O34: ='見積書'!O34 -> 1 | Q34: ='見積書'!Q34 -> 日 | R34: ='見積書'!R34 -> 30000 | U34: ='見積書'!U34 -> 30000
B35: ='見積書'!B35 -> 交通費 | O35: ='見積書'!O35 | Q35: ='見積書'!Q35 | R35: ='見積書'!R35 | U35: ='見積書'!U35 -> 0
B36: ='見積書'!B36 -> 鈴木 | O36: ='見積書'!O36 -> 1 | Q36: ='見積書'!Q36 -> 式 | R36: ='見積書'!R36 -> 38366 | U36: ='見積書'!U36 -> 38366
B37: ='見積書'!B37 -> 安達 | O37: ='見積書'!O37 -> 1 | Q37: ='見積書'!Q37 -> 式 | R37: ='見積書'!R37 -> 11976 | U37: ='見積書'!U37 -> 11976
B38: ='見積書'!B38 -> 原田 | O38: ='見積書'!O38 -> 1 | Q38: ='見積書'!Q38 -> 式 | R38: ='見積書'!R38 -> 63768 | U38: ='見積書'!U38 -> 63768
B39: ='見積書'!B39 | O39: ='見積書'!O39 | Q39: ='見積書'!Q39 | R39: ='見積書'!R39 | U39: ='見積書'!U39 -> 0
B40: ='見積書'!B40 | O40: ='見積書'!O40 | Q40: ='見積書'!Q40 | R40: ='見積書'!R40 | U40: ='見積書'!U40 -> 0
B41: ='見積書'!B41 | O41: ='見積書'!O41 | Q41: ='見積書'!Q41 | R41: ='見積書'!R41 | U41: ='見積書'!U41 -> 0
B42: ='見積書'!B42 | O42: ='見積書'!O42 | Q42: ='見積書'!Q42 | R42: ='見積書'!R42 | U42: ='見積書'!U42 -> 0
B43: ='見積書'!B43 | O43: ='見積書'!O43 | Q43: ='見積書'!Q43 | R43: ='見積書'!R43 | U43: ='見積書'!U43 -> 0
B44: ='見積書'!B44 | O44: ='見積書'!O44 | Q44: ='見積書'!Q44 | R44: ='見積書'!R44 | U44: ='見積書'!U44 -> 0
A45: 17 | B45: ='見積書'!B45 | O45: ='見積書'!O45 | Q45: ='見積書'!Q45 | R45: ='見積書'!R45 | U45: ='見積書'!U45 -> 0
A46: 18 | B46: ='見積書'!B46 | O46: ='見積書'!O46 | Q46: ='見積書'!Q46 | R46: ='見積書'!R46 | U46: ='見積書'!U46 -> 0
...
